Workbook

Sheet RawData
A1: year | B1: corp_code | C1: corp_name | D1: DBO | E1: ServiceCost | F1: BenefitPayment | G1: InterestCost | H1: DiscountRate_Mid | I1: SalaryGrowth_Mid | J1: Duration_Mid | K1: SensitivityDR_1pct | L1: SensitivityDR_1pct_down | M1: SensitivitySG_1pct | N1: SensitivitySG_1pct_down | O1: DBO_prev | P1: drift(%) | Q1: 할인율_prev | R1: 임금상승률_prev | S1: d할인율 | T1: d임금상승률 | U1: 유효듀레이션 | V1: 볼록성
A2: 2015 | B2: 00100601 | C2: 강원에너지 | D2: 39219591
A3: 2016 | B3: 00100601 | C3: 강원에너지 | D3: 7708228 | F3: 50991596 | O3: =D2
A4: 2017 | B4: 00100601 | C4: 강원에너지 | D4: 21905195 | O4: =D3
A5: 2014 | B5: 00100814 | C5: 포스코이앤씨 | D5: 229104000000 | E5: 45628000000 | F5: 21359000000 | G5: 5178000000 | H5: 2.74 | I5: 3.965 | K5: -17718000000 | L5: 19172000000 | M5: 19422000000 | N5: -18138000000 | U5: =(L5-K5)/(2*D5*0.01) | V5: =(L5+K5)/(D5*0.0001)
A6: 2015 | B6: 00100814 | C6: 포스코이앤씨 | D6: 260877000000 | E6: 48768000000 | F6: 23483000000 | G6: 5484000000 | H6: 2.72 | I6: 3.54 | K6: -37100000000 | L6: 39964000000 | M6: 40332000000 | N6: -37816000000 | O6: =D5 | P6: =(E6-F6+G6)/O6*100 | Q6: =H5 | R6: =I5 | S6: =H6-H5 | T6: =I6-I5 | U6: =(L6-K6)/(2*D6*0.01) | V6: =(L6+K6)/(D6*0.0001)
A7: 2016 | B7: 00100814 | C7: 포스코이앤씨 | D7: 225482000000 | E7: 45983000000 | G7: 4958000000 | O7: =D6
A8: 2017 | B8: 00100814 | C8: 포스코이앤씨 | D8: 249111000000 | E8: 32611000000 | O8: =D7
A9: 2018 | B9: 00100814 | C9: 포스코이앤씨 | D9: 314326440000 | E9: 37891584000 | F9: 23719418000 | G9: 6871198000 | O9: =D8 | P9: =(E9-F9+G9)/O9*100
A10: 2019 | B10: 00100814 | C10: 포스코이앤씨 | D10: 404354054000 | E10: 44739086000 | F10: 23012313000 | G10: 6589738000 | O10: =D9 | P10: =(E10-F10+G10)/O10*100
A11: 2014 | B11: 00100939 | C11: 강남제비스코 | D11: 15915000000 | E11: 1985000000 | F11: 1890000000 | G11: 693000000 | H11: 3.91 | I11: 4.78 | J11: 12.92 | K11: -1294725000 | L11: 1512425000 | M11: 1509735000 | N11: -1317171000 | U11: =(L11-K11)/(2*D11*0.01) | V11: =(L11+K11)/(D11*0.0001)
A12: 2015 | B12: 00100939 | C12: 강남제비스코 | D12: 18702000000 | E12: 2719000000 | F12: 1999000000 | G12: 602000000 | H12: 3.44 | I12: 4.85 | J12: 13.8 | K12: -1535486000 | L12: 1785610000 | M12: 1770898000 | N12: -1554384000 | O12: =D11 | P12: =(E12-F12+G12)/O12*100 | Q12: =H11 | R12: =I11 | S12: =H12-H11 | T12: =I12-I11 | U12: =(L12-K12)/(2*D12*0.01) | V12: =(L12+K12)/(D12*0.0001)
A13: 2016 | B13: 00100939 | C13: 강남제비스코 | D13: 22872000000 | E13: 3136000000 | F13: 1506000000 | G13: 626000000 | H13: 3.52 | I13: 4.93 | K13: -1816036800 | L13: 2108798400 | M13: 2111085599 | N13: -1850344800 | O13: =D12 | P13: =(E13-F13+G13)/O13*100 | Q13: =H12 | R13: =I12 | S13: =H13-H12 | T13: =I13-I12 | U13: =(L13-K13)/(2*D13*0.01) | V13: =(L13+K13)/(D13*0.0001)
A14: 2017 | B14: 00100939 | C14: 강남제비스코 | D14: 23399000000 | E14: 3669000000 | F14: 2848000000 | G14: 792000000 | H14: 4.11 | I14: 4.93 | J14: 10.92 | K14: -1638070000 | L14: 1638070000 | M14: 2152770000 | N14: -1890300000 | O14: =D13 | P14: =(E14-F14+G14)/O14*100 | Q14: =H13 | R14: =I13 | S14: =H14-H13 | T14: =I14-I13 | U14: =(L14-K14)/(2*D14*0.01)
A15: 2018 | B15: 00100939 | C15: 강남제비스코 | D15: 29228000000 | E15: 3916000000 | F15: 2626000000 | G15: 944000000 | H15: 3.365 | I15: 3.905 | J15: 8.39 | K15: -2198355200 | L15: 8680000000 | M15: 8690000000 | N15: -2241367600 | O15: =D14 | P15: =(E15-F15+G15)/O15*100 | Q15: =H14 | R15: =I14 | S15: =H15-H14 | T15: =I15-I14 | U15: =(L15-K15)/(2*D15*0.01)
A16: 2019 | B16: 00100939 | C16: 강남제비스코 | D16: 31073000000 | E16: 4042000000 | F16: 2708000000 | G16: 1013000000 | H16: 3.045 | I16: 3.905 | K16: -2556450000 | L16: 2628950000 | M16: 2621350000 | N16: -2320350000 | O16: =D15 | P16: =(E16-F16+G16)/O16*100 | Q16: =H15 | R16: =I15 | S16: =H16-H15 | T16: =I16-I15 | U16: =(L16-K16)/(2*D16*0.01) | V16: =(L16+K16)/(D16*0.0001)
A17: 2020 | B17: 00100939 | C17: 강남제비스코 | D17: 33186000000 | E17: 4012000000 | F17: 2456000000 | G17: 957000000 | H17: 3.025 | I17: 3.925 | K17: -2368029000 | L17: 2724891000 | M17: 2722746000 | N17: -2411253000 | O17: =D16 | P17: =(E17-F17+G17)/O17*100 | Q17: =H16 | R17: =I16 | S17: =H17-H16 | T17: =I17-I16 | U17: =(L17-K17)/(2*D17*0.01) | V17: =(L17+K17)/(D17*0.0001)
A18: 2021 | B18: 00100939 | C18: 강남제비스코 | D18: 55903000000 | E18: 6205000000 | F18: 4720000000 | G18: 1732000000 | H18: 3.69 | I18: 4.905 | K18: -4420637000 | L18: 5126668000 | M18: 9110000000 | N18: -4481558000 | O18: =D17 | P18: =(E18-F18+G18)/O18*100 | Q18: =H17 | R18: =I17 | S18: =H18-H17 | T18: =I18-I17 | U18: =(L18-K18)/(2*D18*0.01) | V18: =(L18+K18)/(D18*0.0001)
A19: 2022 | B19: 00100939 | C19: 강남제비스코 | D19: 48995000000 | E19: 6286000000 | F19: 4290000000 | G19: 2100000000 | H19: 6.06 | I19: 4.92 | J19: 8.29 | K19: -3840000000 | L19: 4430000000 | M19: 4564000000 | N19: -4008000000 | O19: =D18 | P19: =(E19-F19+G19)/O19*100 | Q19: =H18 | R19: =I18 | S19: =H19-H18 | T19: =I19-I18 | U19: =(L19-K19)/(2*D19*0.01) | V19: =(L19+K19)/(D19*0.0001)
A20: 2023 | B20: 00100939 | C20: 강남제비스코 | D20: 56942000000 | E20: 5370000000 | F20: 2621000000 | G20: 2970000000 | H20: 5.175 | I20: 4.905 | J20: 7.59 | K20: -3838000000 | L20: 4395542400 | M20: 4445000000 | N20: -3956819000 | O20: =D19 | P20: =(E20-F20+G20)/O20*100 | Q20: =H19 | R20: =I19 | S20: =H20-H19 | T20: =I20-I19 | U20: =(L20-K20)/(2*D20*0.01) | V20: =(L20+K20)/(D20*0.0001)
A21: 2024 | B21: 00100939 | C21: 강남제비스코 | D21: 66870000000 | E21: 5773000000 | F21: 2722000000 | G21: 2940000000 | H21: 4.575 | I21: 5.505 | J21: 7.43 | K21: -4426764000 | L21: 5073798000 | M21: 5119050000 | N21: -4547760000 | O21: =D20 | P21: =(E21-F21+G21)/O21*100 | Q21: =H20 | R21: =I20 | S21: =H21-H20 | T21: =I21-I20 | U21: =(L21-K21)/(2*D21*0.01) | V21: =(L21+K21)/(D21*0.0001)
A22: 2025 | B22: 00100939 | C22: 강남제비스코 | D22: 65142000000 | E22: 6276000000 | F22: 3780000000 | G22: 3069000000 | H22: 4.93 | I22: 4.825 | J22: 7.98 | K22: -4415000000 | L22: 5026000000 | M22: 5210000000 | N22: -4643000000 | O22: =D21 | P22: =(E22-F22+G22)/O22*100 | Q22: =H21 | R22: =I21 | S22: =H22-H21 | T22: =I22-I21 | U22: =(L22-K22)/(2*D22*0.01) | V22: =(L22+K22)/(D22*0.0001)
A23: 2014 | B23: 00101044 | C23: 에이프로젠바이오로직스 | D23: 4902958000 | E23: 698568000 | F23: 316634000 | G23: 131666000 | H23: 2.685 | I23: 5.25 | K23: -271879000 | L23: 308009000 | M23: 297317000 | N23: -268268000 | U23: =(L23-K23)/(2*D23*0.01) | V23: =(L23+K23)/(D23*0.0001)
A24: 2015 | B24: 00101044 | C24: 에이프로젠바이오로직스 | D24: 4692436000 | E24: 919637000 | F24: 835226000 | G24: 106200000 | H24: 2.305 | I24: 5 | K24: -250749000 | L24: 284077000 | M24: 273865000 | N24: -247135000 | O24: =D23 | P24: =(E24-F24+G24)/O24*100 | Q24: =H23 | R24: =I23 | S24: =H24-H23 | T24: =I24-I23 | U24: =(L24-K24)/(2*D24*0.01) | V24: =(L24+K24)/(D24*0.0001)
A25: 2016 | B25: 00101044 | C25: 에이프로젠바이오로직스 | D25: 5373620000 | E25: 935288000 | F25: 1052055000 | G25: 85322000 | H25: 2.345 | I25: 5.2 | K25: -292170000 | L25: 331161000 | M25: 318717000 | N25: -287531000 | O25: =D24 | P25: =(E25-F25+G25)/O25*100 | Q25: =H24 | R25: =I24 | S25: =H25-H24 | T25: =I25-I24 | U25: =(L25-K25)/(2*D25*0.01) | V25: =(L25+K25)/(D25*0.0001)
A26: 2017 | B26: 00101044 | C26: 에이프로젠바이오로직스 | D26: 5973217000 | E26: 1000944000 | F26: 192369000 | G26: 100458000 | H26: 2.77 | I26: 5.41 | K26: -352840000 | L26: 404770000 | M26: 390233000 | N26: -347852000 | O26: =D25 | P26: =(E26-F26+G26)/O26*100 | Q26: =H25 | R26: =I25 | S26: =H26-H25 | T26: =I26-I25 | U26: =(L26-K26)/(2*D26*0.01) | V26: =(L26+K26)/(D26*0.0001)
A27: 2018 | B27: 00101044 | C27: 에이프로젠바이오로직스 | D27: 7126349000 | E27: 1036088000 | F27: 441286000 | G27: 126298000 | H27: 2.255 | I27: 5.22 | K27: -417829000 | L27: 479310000 | M27: 460646000 | N27: -410793000 | O27: =D26 | P27: =(E27-F27+G27)/O27*100 | Q27: =H26 | R27: =I26 | S27: =H27-H26 | T27: =I27-I26 | U27: =(L27-K27)/(2*D27*0.01) | V27: =(L27+K27)/(D27*0.0001)
A28: 2019 | B28: 00101044 | C28: 에이프로젠바이오로직스 | D28: 9347250000 | E28: 1213619000 | F28: 403029000 | G28: 124921000 | H28: 1.94 | I28: 5.3 | J28: 7.05 | K28: -630067000 | L28: 732443000 | M28: 700487000 | N28: -617074000 | O28: =D27 | P28: =(E28-F28+G28)/O28*100 | Q28: =H27 | R28: =I27 | S28: =H28-H27 | T28: =I28-I27 | U28: =(L28-K28)/(2*D28*0.01) | V28: =(L28+K28)/(D28*0.0001)
A29: 2020 | B29: 00101044 | C29: 에이프로젠바이오로직스 | D29: 9946133000 | E29: 1506376000 | F29: 577395000 | G29: 140672000 | H29: 1.815 | I29: 4.9 | J29: 7.51 | K29: -509046000 | L29: 582992000 | M29: 557898000 | N29: -498670000 | O29: =D28 | P29: =(E29-F29+G29)/O29*100 | Q29: =H28 | R29: =I28 | S29: =H29-H28 | T29: =I29-I28 | U29: =(L29-K29)/(2*D29*0.01) | V29: =(L29+K29)/(D29*0.0001)
A30: 2021 | B30: 00101044 | C30: 에이프로젠바이오로직스 | D30: 9487019000 | E30: 1349281000 | F30: 763199000 | G30: 126449000 | H30: 2.4 | I30: 3.69 | J30: 5.985 | K30: -431654000 | L30: 492198000 | M30: 476700000 | N30: -427361000 | O30: =D29 | P30: =(E30-F30+G30)/O30*100 | Q30: =H29 | R30: =I29 | S30: =H30-H29 | T30: =I30-I29 | U30: =(L30-K30)/(2*D30*0.01) | V30: =(L30+K30)/(D30*0.0001)
A31: 2022 | B31: 00101044 | C31: 에이프로젠바이오로직스 | D31: 11096013000 | E31: 1234175000 | F31: 1591298000 | G31: 151358000 | H31: 5.23 | I31: 4.895 | J31: 7.09 | K31: -621157000 | L31: 733977000 | M31: 730743000 | N31: -629475000 | O31: =D30 | P31: =(E31-F31+G31)/O31*100 | Q31: =H30 | R31: =I30 | S31: =H31-H30 | T31: =I31-I30 | U31: =(L31-K31)/(2*D31*0.01) | V31: =(L31+K31)/(D31*0.0001)
A32: 2023 | B32: 00101044 | C32: 에이프로젠바이오로직스 | D32: 11693776000 | E32: 2219739000 | F32: 1492541000 | G32: 384674000 | H32: 4.125 | I32: 4.905 | J32: 8.595 | K32: -615704000 | L32: -621157000 | M32: 702244000 | N32: 730743000 | O32: =D31 | P32: =(E32-F32+G32)/O32*100 | Q32: =H31 | R32: =I31 | S32: =H32-H31 | T32: =I32-I31
A33: 2024 | B33: 00101044 | C33: 에이프로젠바이오로직스 | D33: 14042701000 | E33: 2196210000 | F33: 1266014000 | G33: 337542000 | H33: 3.595 | I33: 4.91 | J33: 8.335 | K33: -1001800000 | L33: 1212950000 | M33: 1188254000 | N33: -1001154000 | O33: =D32 | P33: =(E33-F33+G33)/O33*100 | Q33: =H32 | R33: =I32 | S33: =H33-H32 | T33: =I33-I32 | U33: =(L33-K33)/(2*D33*0.01) | V33: =(L33+K33)/(D33*0.0001)
A34: 2025 | B34: 00101044 | C34: 에이프로젠바이오로직스 | D34: 15673830376 | E34: 2695163011 | F34: 2930175246 | G34: 384775683 | H34: 4.015 | I34: 4.75 | J34: 8.725 | K34: -871138277 | L34: 1013431481 | M34: 995198460 | N34: -872505023 | O34: =D33 | P34: =(E34-F34+G34)/O34*100 | Q34: =H33 | R34: =I33 | S34: =H34-H33 | T34: =I34-I33 | U34: =(L34-K34)/(2*D34*0.01) | V34: =(L34+K34)/(D34*0.0001)
A35: 2014 | B35: 00101220 | C35: KG케미칼 | D35: 16323881000 | E35: 4035787000 | F35: 1772451000 | H35: 3.08 | I35: 4.96 | J35: 10.38 | K35: -1063767000 | L35: 1174527000 | M35: 1201877000 | N35: -1003839000 | U35: =(L35-K35)/(2*D35*0.01) | V35: =(L35+K35)/(D35*0.0001)
A36: 2015 | B36: 00101220 | C36: KG케미칼 | D36: 19721674000 | E36: 4830208000 | F36: 2865813000 | H36: 2.625 | I36: 4.67 | K36: -1184271000 | L36: 1333190000 | M36: 1319867000 | N36: -1195273000 | O36: =D35 | Q36: =H35 | R36: =I35 | S36: =H36-H35 | T36: =I36-I35 | U36: =(L36-K36)/(2*D36*0.01) | V36: =(L36+K36)/(D36*0.0001)
A37: 2016 | B37: 00101220 | C37: KG케미칼 | D37: 22425287000 | E37: 4300860000 | F37: 3127592000 | G37: 546526000 | H37: 2.845 | I37: 4.07 | J37: 8.635 | K37: -1146249000 | L37: 1298746000 | M37: 1290479000 | N37: -1160532000 | O37: =D36 | P37: =(E37-F37+G37)/O37*100 | Q37: =H36 | R37: =I36 | S37: =H37-H36 | T37: =I37-I36 | U37: =(L37-K37)/(2*D37*0.01) | V37: =(L37+K37)/(D37*0.0001)
A38: 2017 | B38: 00101220 | C38: KG케미칼 | D38: 33329615000 | E38: 6100343000 | F38: 6428735000 | G38: 562014000 | H38: 3.285 | I38: 3 | J38: 7.62 | K38: -1751729000 | L38: 1985889000 | M38: 1974716000 | N38: -1769627000 | O38: =D37 | P38: =(E38-F38+G38)/O38*100 | Q38: =H37 | R38: =I37 | S38: =H38-H37 | T38: =I38-I37 | U38: =(L38-K38)/(2*D38*0.01) | V38: =(L38+K38)/(D38*0.0001)
A39: 2018 | B39: 00101220 | C39: KG케미칼 | D39: 37201863000 | E39: 6741870000 | F39: 6219048000 | G39: 765025000 | H39: 2.665 | I39: 3.43 | K39: -1453092000 | L39: 2160830000 | M39: 2137202000 | N39: -1464422000 | O39: =D38 | P39: =(E39-F39+G39)/O39*100 | Q39: =H38 | R39: =I38 | S39: =H39-H38 | T39: =I39-I38 | U39: =(L39-K39)/(2*D39*0.01) | V39: =(L39+K39)/(D39*0.0001)
A40: 2019 | B40: 00101220 | C40: KG케미칼 | D40: 142778647000 | E40: 9813536000 | F40: 9812639000 | G40: 1706278000 | H40: 2.445 | I40: 3.48 | K40: -13417177000 | L40: 15843021000 | M40: 15477242000 | N40: -13468543000 | O40: =D39 | P40: =(E40-F40+G40)/O40*100 | Q40: =H39 | R40: =I39 | S40: =H40-H39 | T40: =I40-I39 | U40: =(L40-K40)/(2*D40*0.01) | V40: =(L40+K40)/(D40*0.0001)
...

Sheet Drift
A1: [Drift = (SC-BP+IC)/DBO_{t-1}]
A2: 연도 | B2: 건수 | C2: drift 평균(%) | D2: drift 중앙값(%)
A3: 2015 | B3: =COUNTIFS(RawData!$A:$A,A3,RawData!$P:$P,">-100",RawData!$P:$P,"<100") | C3: =AVERAGEIFS(RawData!$P:$P,RawData!$A:$A,A3,RawData!$P:$P,">-100",RawData!$P:$P,"<100") | D3: =MEDIAN(_xlfn._xlws.FILTER(RawData!$P$2:$P$21560,(RawData!$A$2:$A$21560=A3)*(RawData!$P$2:$P$21560<>0)))
A4: 2016 | B4: =COUNTIFS(RawData!$A:$A,A4,RawData!$P:$P,">-100",RawData!$P:$P,"<100") | C4: =AVERAGEIFS(RawData!$P:$P,RawData!$A:$A,A4,RawData!$P:$P,">-100",RawData!$P:$P,"<100") | D4: =MEDIAN(_xlfn._xlws.FILTER(RawData!$P$2:$P$21560,(RawData!$A$2:$A$21560=A4)*(RawData!$P$2:$P$21560<>0)))
A5: 2017 | B5: =COUNTIFS(RawData!$A:$A,A5,RawData!$P:$P,">-100",RawData!$P:$P,"<100") | C5: =AVERAGEIFS(RawData!$P:$P,RawData!$A:$A,A5,RawData!$P:$P,">-100",RawData!$P:$P,"<100") | D5: =MEDIAN(_xlfn._xlws.FILTER(RawData!$P$2:$P$21560,(RawData!$A$2:$A$21560=A5)*(RawData!$P$2:$P$21560<>0)))
A6: 2018 | B6: =COUNTIFS(RawData!$A:$A,A6,RawData!$P:$P,">-100",RawData!$P:$P,"<100") | C6: =AVERAGEIFS(RawData!$P:$P,RawData!$A:$A,A6,RawData!$P:$P,">-100",RawData!$P:$P,"<100") | D6: =MEDIAN(_xlfn._xlws.FILTER(RawData!$P$2:$P$21560,(RawData!$A$2:$A$21560=A6)*(RawData!$P$2:$P$21560<>0)))
A7: 2019 | B7: =COUNTIFS(RawData!$A:$A,A7,RawData!$P:$P,">-100",RawData!$P:$P,"<100") | C7: =AVERAGEIFS(RawData!$P:$P,RawData!$A:$A,A7,RawData!$P:$P,">-100",RawData!$P:$P,"<100") | D7: =MEDIAN(_xlfn._xlws.FILTER(RawData!$P$2:$P$21560,(RawData!$A$2:$A$21560=A7)*(RawData!$P$2:$P$21560<>0)))
A8: 2020 | B8: =COUNTIFS(RawData!$A:$A,A8,RawData!$P:$P,">-100",RawData!$P:$P,"<100") | C8: =AVERAGEIFS(RawData!$P:$P,RawData!$A:$A,A8,RawData!$P:$P,">-100",RawData!$P:$P,"<100") | D8: =MEDIAN(_xlfn._xlws.FILTER(RawData!$P$2:$P$21560,(RawData!$A$2:$A$21560=A8)*(RawData!$P$2:$P$21560<>0)))
A9: 2021 | B9: =COUNTIFS(RawData!$A:$A,A9,RawData!$P:$P,">-100",RawData!$P:$P,"<100") | C9: =AVERAGEIFS(RawData!$P:$P,RawData!$A:$A,A9,RawData!$P:$P,">-100",RawData!$P:$P,"<100") | D9: =MEDIAN(_xlfn._xlws.FILTER(RawData!$P$2:$P$21560,(RawData!$A$2:$A$21560=A9)*(RawData!$P$2:$P$21560<>0)))
A10: 2022 | B10: =COUNTIFS(RawData!$A:$A,A10,RawData!$P:$P,">-100",RawData!$P:$P,"<100") | C10: =AVERAGEIFS(RawData!$P:$P,RawData!$A:$A,A10,RawData!$P:$P,">-100",RawData!$P:$P,"<100") | D10: =MEDIAN(_xlfn._xlws.FILTER(RawData!$P$2:$P$21560,(RawData!$A$2:$A$21560=A10)*(RawData!$P$2:$P$21560<>0)))
A11: 2023 | B11: =COUNTIFS(RawData!$A:$A,A11,RawData!$P:$P,">-100",RawData!$P:$P,"<100") | C11: =AVERAGEIFS(RawData!$P:$P,RawData!$A:$A,A11,RawData!$P:$P,">-100",RawData!$P:$P,"<100") | D11: =MEDIAN(_xlfn._xlws.FILTER(RawData!$P$2:$P$21560,(RawData!$A$2:$A$21560=A11)*(RawData!$P$2:$P$21560<>0)))
A12: 2024 | B12: =COUNTIFS(RawData!$A:$A,A12,RawData!$P:$P,">-100",RawData!$P:$P,"<100") | C12: =AVERAGEIFS(RawData!$P:$P,RawData!$A:$A,A12,RawData!$P:$P,">-100",RawData!$P:$P,"<100") | D12: =MEDIAN(_xlfn._xlws.FILTER(RawData!$P$2:$P$21560,(RawData!$A$2:$A$21560=A12)*(RawData!$P$2:$P$21560<>0)))
A13: 2025 | B13: =COUNTIFS(RawData!$A:$A,A13,RawData!$P:$P,">-100",RawData!$P:$P,"<100") | C13: =AVERAGEIFS(RawData!$P:$P,RawData!$A:$A,A13,RawData!$P:$P,">-100",RawData!$P:$P,"<100") | D13: =MEDIAN(_xlfn._xlws.FILTER(RawData!$P$2:$P$21560,(RawData!$A$2:$A$21560=A13)*(RawData!$P$2:$P$21560<>0)))
A15: 평균의 평균 | C15: =AVERAGE(C3:C13) | D15: =AVERAGE(D3:D13)
A17: [참고: 소수 변환]
A18: drift_mean | C18: =C15/100
A19: drift_median | C19: =D15/100

Sheet YearlyStats
A1: [연도별 할인율/임금상승률 평균]
A2: 연도 | B2: 건수 | C2: 할인율 avg(%) | D2: 임금상승률 avg(%) | E2: Δavg_할인율(%p) | F2: Δavg_임금상승률(%p)
A3: 2014 | B3: =COUNTIFS(RawData!$A:$A,A3,RawData!$H:$H,">0",RawData!$I:$I,">0") | C3: =AVERAGEIFS(RawData!$H:$H,RawData!$A:$A,A3,RawData!$H:$H,">0",RawData!$I:$I,">0") | D3: =AVERAGEIFS(RawData!$I:$I,RawData!$A:$A,A3,RawData!$H:$H,">0",RawData!$I:$I,">0")
A4: 2015 | B4: =COUNTIFS(RawData!$A:$A,A4,RawData!$H:$H,">0",RawData!$I:$I,">0") | C4: =AVERAGEIFS(RawData!$H:$H,RawData!$A:$A,A4,RawData!$H:$H,">0",RawData!$I:$I,">0") | D4: =AVERAGEIFS(RawData!$I:$I,RawData!$A:$A,A4,RawData!$H:$H,">0",RawData!$I:$I,">0") | E4: =C4-C3 | F4: =D4-D3
A5: 2016 | B5: =COUNTIFS(RawData!$A:$A,A5,RawData!$H:$H,">0",RawData!$I:$I,">0") | C5: =AVERAGEIFS(RawData!$H:$H,RawData!$A:$A,A5,RawData!$H:$H,">0",RawData!$I:$I,">0") | D5: =AVERAGEIFS(RawData!$I:$I,RawData!$A:$A,A5,RawData!$H:$H,">0",RawData!$I:$I,">0") | E5: =C5-C4 | F5: =D5-D4
A6: 2017 | B6: =COUNTIFS(RawData!$A:$A,A6,RawData!$H:$H,">0",RawData!$I:$I,">0") | C6: =AVERAGEIFS(RawData!$H:$H,RawData!$A:$A,A6,RawData!$H:$H,">0",RawData!$I:$I,">0") | D6: =AVERAGEIFS(RawData!$I:$I,RawData!$A:$A,A6,RawData!$H:$H,">0",RawData!$I:$I,">0") | E6: =C6-C5 | F6: =D6-D5
A7: 2018 | B7: =COUNTIFS(RawData!$A:$A,A7,RawData!$H:$H,">0",RawData!$I:$I,">0") | C7: =AVERAGEIFS(RawData!$H:$H,RawData!$A:$A,A7,RawData!$H:$H,">0",RawData!$I:$I,">0") | D7: =AVERAGEIFS(RawData!$I:$I,RawData!$A:$A,A7,RawData!$H:$H,">0",RawData!$I:$I,">0") | E7: =C7-C6 | F7: =D7-D6
A8: 2019 | B8: =COUNTIFS(RawData!$A:$A,A8,RawData!$H:$H,">0",RawData!$I:$I,">0") | C8: =AVERAGEIFS(RawData!$H:$H,RawData!$A:$A,A8,RawData!$H:$H,">0",RawData!$I:$I,">0") | D8: =AVERAGEIFS(RawData!$I:$I,RawData!$A:$A,A8,RawData!$H:$H,">0",RawData!$I:$I,">0") | E8: =C8-C7 | F8: =D8-D7
A9: 2020 | B9: =COUNTIFS(RawData!$A:$A,A9,RawData!$H:$H,">0",RawData!$I:$I,">0") | C9: =AVERAGEIFS(RawData!$H:$H,RawData!$A:$A,A9,RawData!$H:$H,">0",RawData!$I:$I,">0") | D9: =AVERAGEIFS(RawData!$I:$I,RawData!$A:$A,A9,RawData!$H:$H,">0",RawData!$I:$I,">0") | E9: =C9-C8 | F9: =D9-D8
A10: 2021 | B10: =COUNTIFS(RawData!$A:$A,A10,RawData!$H:$H,">0",RawData!$I:$I,">0") | C10: =AVERAGEIFS(RawData!$H:$H,RawData!$A:$A,A10,RawData!$H:$H,">0",RawData!$I:$I,">0") | D10: =AVERAGEIFS(RawData!$I:$I,RawData!$A:$A,A10,RawData!$H:$H,">0",RawData!$I:$I,">0") | E10: =C10-C9 | F10: =D10-D9
A11: 2022 | B11: =COUNTIFS(RawData!$A:$A,A11,RawData!$H:$H,">0",RawData!$I:$I,">0") | C11: =AVERAGEIFS(RawData!$H:$H,RawData!$A:$A,A11,RawData!$H:$H,">0",RawData!$I:$I,">0") | D11: =AVERAGEIFS(RawData!$I:$I,RawData!$A:$A,A11,RawData!$H:$H,">0",RawData!$I:$I,">0") | E11: =C11-C10 | F11: =D11-D10
A12: 2023 | B12: =COUNTIFS(RawData!$A:$A,A12,RawData!$H:$H,">0",RawData!$I:$I,">0") | C12: =AVERAGEIFS(RawData!$H:$H,RawData!$A:$A,A12,RawData!$H:$H,">0",RawData!$I:$I,">0") | D12: =AVERAGEIFS(RawData!$I:$I,RawData!$A:$A,A12,RawData!$H:$H,">0",RawData!$I:$I,">0") | E12: =C12-C11 | F12: =D12-D11
A13: 2024 | B13: =COUNTIFS(RawData!$A:$A,A13,RawData!$H:$H,">0",RawData!$I:$I,">0") | C13: =AVERAGEIFS(RawData!$H:$H,RawData!$A:$A,A13,RawData!$H:$H,">0",RawData!$I:$I,">0") | D13: =AVERAGEIFS(RawData!$I:$I,RawData!$A:$A,A13,RawData!$H:$H,">0",RawData!$I:$I,">0") | E13: =C13-C12 | F13: =D13-D12
A14: 2025 | B14: =COUNTIFS(RawData!$A:$A,A14,RawData!$H:$H,">0",RawData!$I:$I,">0") | C14: =AVERAGEIFS(RawData!$H:$H,RawData!$A:$A,A14,RawData!$H:$H,">0",RawData!$I:$I,">0") | D14: =AVERAGEIFS(RawData!$I:$I,RawData!$A:$A,A14,RawData!$H:$H,">0",RawData!$I:$I,">0") | E14: =C14-C13 | F14: =D14-D13
A16: 구분 | C16: 할인율 | D16: 임금상승률
A17: 장기균형(%) | C17: =AVERAGE(C3:C14) | D17: =AVERAGE(D3:D14)
A18: 현재값(%) | C18: =C14 | D18: =D14
A19: 변동성(%) | C19: =STDEV(C3:C14) | D19: =STDEV(D3:D14)
A21: [소수 변환]
A22: Y_inf | C22: =C17/100
A23: I_inf | C23: =D17/100
A24: Y_init | C24: =C18/100
A25: I_init | C25: =D18/100
A26: Vol_y | C26: =C19/100
A27: Vol_i | C27: =D19/100
A29: [상관계수]
A30: rho (연도평균 Δ상관) | C30: =CORREL(E4:E14,F4:F14)

Sheet Velocity
A1: [CV: 패널 MLE (X_inf 고정, 절편 없는 OLS)]
A2: Vasicek: ΔX(i,t) = CV × (X_inf - X(i,t-1)) + ε
A4: 파라미터 | B4: 수식 | C4: 값
A5: CV_y (할인율) | B5: Σ(d할인율×gap)/Σ(gap²), gap=Y_inf-할인율_prev | C5: =SUMPRODUCT(1*ISNUMBER(RawData!$S$2:$S$21560)*RawData!$S$2:$S$21560*1*ISNUMBER(RawData!$Q$2:$Q$21560)*(YearlyStats!C17-RawData!$Q$2:$Q$21560))/SUMPRODUCT(1*ISNUMBER(RawData!$Q$2:$Q$21560)*((YearlyStats!C17-RawData!$Q$2:$Q$21560)^2))
A6: CV_i (임금상승률) | B6: Σ(d임금상승률×gap)/Σ(gap²), gap=I_inf-임금상승률_prev | C6: =SUMPRODUCT(1*ISNUMBER(RawData!$T$2:$T$21560)*RawData!$T$2:$T$21560*1*ISNUMBER(RawData!$R$2:$R$21560)*(YearlyStats!D17-RawData!$R$2:$R$21560))/SUMPRODUCT(1*ISNUMBER(RawData!$R$2:$R$21560)*((YearlyStats!D17-RawData!$R$2:$R$21560)^2))
A7: 유효 쌍 수 (할인율) | C7: =SUMPRODUCT((ISNUMBER(RawData!$S$2:$S$21560))*1)
A8: 유효 쌍 수 (임금상승률) | C8: =SUMPRODUCT((ISNUMBER(RawData!$T$2:$T$21560))*1)

Sheet Duration
A1: [Duration & 볼록성 (2025)]
A2: 항목 | B2: 수식 | C2: 값 | D2: 건수
A3: [연도별 추이]
A4: 연도 | B4: Duration(LLM) | C4: 건수 | D4: 유효듀레이션 | E4: 건수 | F4: 볼록성 | G4: 건수
A5: 2014 | B5: =AVERAGEIFS(RawData!$J:$J,RawData!$A:$A,A5,RawData!$J:$J,">0") | C5: =COUNTIFS(RawData!$A:$A,A5,RawData!$J:$J,">0") | D5: =AVERAGEIFS(RawData!$U:$U,RawData!$A:$A,A5,RawData!$U:$U,">0") | E5: =COUNTIFS(RawData!$A:$A,A5,RawData!$U:$U,">0") | F5: =AVERAGEIFS(RawData!$V:$V,RawData!$A:$A,A5,RawData!$V:$V,">0") | G5: =COUNTIFS(RawData!$A:$A,A5,RawData!$V:$V,">0")
A6: 2015 | B6: =AVERAGEIFS(RawData!$J:$J,RawData!$A:$A,A6,RawData!$J:$J,">0") | C6: =COUNTIFS(RawData!$A:$A,A6,RawData!$J:$J,">0") | D6: =AVERAGEIFS(RawData!$U:$U,RawData!$A:$A,A6,RawData!$U:$U,">0") | E6: =COUNTIFS(RawData!$A:$A,A6,RawData!$U:$U,">0") | F6: =AVERAGEIFS(RawData!$V:$V,RawData!$A:$A,A6,RawData!$V:$V,">0") | G6: =COUNTIFS(RawData!$A:$A,A6,RawData!$V:$V,">0")
A7: 2016 | B7: =AVERAGEIFS(RawData!$J:$J,RawData!$A:$A,A7,RawData!$J:$J,">0") | C7: =COUNTIFS(RawData!$A:$A,A7,RawData!$J:$J,">0") | D7: =AVERAGEIFS(RawData!$U:$U,RawData!$A:$A,A7,RawData!$U:$U,">0") | E7: =COUNTIFS(RawData!$A:$A,A7,RawData!$U:$U,">0") | F7: =AVERAGEIFS(RawData!$V:$V,RawData!$A:$A,A7,RawData!$V:$V,">0") | G7: =COUNTIFS(RawData!$A:$A,A7,RawData!$V:$V,">0")
A8: 2017 | B8: =AVERAGEIFS(RawData!$J:$J,RawData!$A:$A,A8,RawData!$J:$J,">0") | C8: =COUNTIFS(RawData!$A:$A,A8,RawData!$J:$J,">0") | D8: =AVERAGEIFS(RawData!$U:$U,RawData!$A:$A,A8,RawData!$U:$U,">0") | E8: =COUNTIFS(RawData!$A:$A,A8,RawData!$U:$U,">0") | F8: =AVERAGEIFS(RawData!$V:$V,RawData!$A:$A,A8,RawData!$V:$V,">0") | G8: =COUNTIFS(RawData!$A:$A,A8,RawData!$V:$V,">0")
A9: 2018 | B9: =AVERAGEIFS(RawData!$J:$J,RawData!$A:$A,A9,RawData!$J:$J,">0") | C9: =COUNTIFS(RawData!$A:$A,A9,RawData!$J:$J,">0") | D9: =AVERAGEIFS(RawData!$U:$U,RawData!$A:$A,A9,RawData!$U:$U,">0") | E9: =COUNTIFS(RawData!$A:$A,A9,RawData!$U:$U,">0") | F9: =AVERAGEIFS(RawData!$V:$V,RawData!$A:$A,A9,RawData!$V:$V,">0") | G9: =COUNTIFS(RawData!$A:$A,A9,RawData!$V:$V,">0")
A10: 2019 | B10: =AVERAGEIFS(RawData!$J:$J,RawData!$A:$A,A10,RawData!$J:$J,">0") | C10: =COUNTIFS(RawData!$A:$A,A10,RawData!$J:$J,">0") | D10: =AVERAGEIFS(RawData!$U:$U,RawData!$A:$A,A10,RawData!$U:$U,">0") | E10: =COUNTIFS(RawData!$A:$A,A10,RawData!$U:$U,">0") | F10: =AVERAGEIFS(RawData!$V:$V,RawData!$A:$A,A10,RawData!$V:$V,">0") | G10: =COUNTIFS(RawData!$A:$A,A10,RawData!$V:$V,">0")
A11: 2020 | B11: =AVERAGEIFS(RawData!$J:$J,RawData!$A:$A,A11,RawData!$J:$J,">0") | C11: =COUNTIFS(RawData!$A:$A,A11,RawData!$J:$J,">0") | D11: =AVERAGEIFS(RawData!$U:$U,RawData!$A:$A,A11,RawData!$U:$U,">0") | E11: =COUNTIFS(RawData!$A:$A,A11,RawData!$U:$U,">0") | F11: =AVERAGEIFS(RawData!$V:$V,RawData!$A:$A,A11,RawData!$V:$V,">0") | G11: =COUNTIFS(RawData!$A:$A,A11,RawData!$V:$V,">0")
A12: 2021 | B12: =AVERAGEIFS(RawData!$J:$J,RawData!$A:$A,A12,RawData!$J:$J,">0") | C12: =COUNTIFS(RawData!$A:$A,A12,RawData!$J:$J,">0") | D12: =AVERAGEIFS(RawData!$U:$U,RawData!$A:$A,A12,RawData!$U:$U,">0") | E12: =COUNTIFS(RawData!$A:$A,A12,RawData!$U:$U,">0") | F12: =AVERAGEIFS(RawData!$V:$V,RawData!$A:$A,A12,RawData!$V:$V,">0") | G12: =COUNTIFS(RawData!$A:$A,A12,RawData!$V:$V,">0")
A13: 2022 | B13: =AVERAGEIFS(RawData!$J:$J,RawData!$A:$A,A13,RawData!$J:$J,">0") | C13: =COUNTIFS(RawData!$A:$A,A13,RawData!$J:$J,">0") | D13: =AVERAGEIFS(RawData!$U:$U,RawData!$A:$A,A13,RawData!$U:$U,">0") | E13: =COUNTIFS(RawData!$A:$A,A13,RawData!$U:$U,">0") | F13: =AVERAGEIFS(RawData!$V:$V,RawData!$A:$A,A13,RawData!$V:$V,">0") | G13: =COUNTIFS(RawData!$A:$A,A13,RawData!$V:$V,">0")
A14: 2023 | B14: =AVERAGEIFS(RawData!$J:$J,RawData!$A:$A,A14,RawData!$J:$J,">0") | C14: =COUNTIFS(RawData!$A:$A,A14,RawData!$J:$J,">0") | D14: =AVERAGEIFS(RawData!$U:$U,RawData!$A:$A,A14,RawData!$U:$U,">0") | E14: =COUNTIFS(RawData!$A:$A,A14,RawData!$U:$U,">0") | F14: =AVERAGEIFS(RawData!$V:$V,RawData!$A:$A,A14,RawData!$V:$V,">0") | G14: =COUNTIFS(RawData!$A:$A,A14,RawData!$V:$V,">0")
A15: 2024 | B15: =AVERAGEIFS(RawData!$J:$J,RawData!$A:$A,A15,RawData!$J:$J,">0") | C15: =COUNTIFS(RawData!$A:$A,A15,RawData!$J:$J,">0") | D15: =AVERAGEIFS(RawData!$U:$U,RawData!$A:$A,A15,RawData!$U:$U,">0") | E15: =COUNTIFS(RawData!$A:$A,A15,RawData!$U:$U,">0") | F15: =AVERAGEIFS(RawData!$V:$V,RawData!$A:$A,A15,RawData!$V:$V,">0") | G15: =COUNTIFS(RawData!$A:$A,A15,RawData!$V:$V,">0")
A16: 2025 | B16: =AVERAGEIFS(RawData!$J:$J,RawData!$A:$A,A16,RawData!$J:$J,">0") | C16: =COUNTIFS(RawData!$A:$A,A16,RawData!$J:$J,">0") | D16: =AVERAGEIFS(RawData!$U:$U,RawData!$A:$A,A16,RawData!$U:$U,">0") | E16: =COUNTIFS(RawData!$A:$A,A16,RawData!$U:$U,">0") | F16: =AVERAGEIFS(RawData!$V:$V,RawData!$A:$A,A16,RawData!$V:$V,">0") | G16: =COUNTIFS(RawData!$A:$A,A16,RawData!$V:$V,">0")
A18: [요약]
A19: 구분 | B19: Duration(LLM) | D19: 유효듀레이션 | F19: 볼록성
A20: 전체 평균 | B20: =AVERAGE(B5:B16) | D20: =AVERAGE(D5:D16) | F20: =AVERAGE(F5:F16)
A21: 최근 3년 평균 | B21: =AVERAGE(B14:B16) | D21: =AVERAGE(D14:D16) | F21: =AVERAGE(F14:F16)
A22: 최근 5년 평균 | B22: =AVERAGE(B12:B16) | D22: =AVERAGE(D12:D16) | F22: =AVERAGE(F12:F16)
A23: 최신(2025) | B23: =B16 | D23: =D16 | F23: =F16
A25: [사용 값 선택] | B25: ← 위 요약에서 원하는 셀 참조 입력
A26: Duration 선택 | B26: =AVERAGE(D12:D16) | C26: ← 유효듀레이션 최근 5년 평균
A27: 볼록성 선택 | B27: =AVERAGE(F14:F16) | C27: ← 볼록성 최근 3년 평균
A28: 볼록성 연간조정(소수) | B28: =0.5*B27*(YearlyStats!C26)^2

Sheet Parameters
A1: [파라미터 요약 — 모든 값이 다른 시트 수식 참조]
A2: 파라미터 | B2: 의미 | C2: 값 (소수) | D2: 값 (%) | E2: 출처 셀
A3: Y_inf | B3: 할인율 장기균형 | C3: =YearlyStats!C22 | D3: =YearlyStats!C17 | E3: YearlyStats!C17
A4: Y_init | B4: 할인율 현재값(2025) | C4: =YearlyStats!C24 | D4: =YearlyStats!C18 | E4: YearlyStats!C18
A5: CV_y | B5: 할인율 회귀속도 | C5: =Velocity!C5 | E5: Velocity!C5
A6: Vol_y | B6: 할인율 변동성 | C6: =YearlyStats!C26 | D6: =YearlyStats!C19 | E6: YearlyStats!C19
A7: Duration | B7: 유효듀레이션 (Duration 시트 선택) | C7: =Duration!B26 | E7: Duration!B26
A8: 볼록성 | B8: 볼록성 | C8: =Duration!B27 | E8: Duration!B27
A9: drift_mean | B9: drift 보정평균 | C9: =Drift!C18 | D9: =Drift!C15 | E9: Drift!C18
A10: drift_median | B10: drift 보정중앙값 | C10: =Drift!C19 | D10: =Drift!D15 | E10: Drift!C19
A11: rho | B11: 상관계수 (참고) | C11: =YearlyStats!C30 | E11: YearlyStats!C30
A12: 볼록성_adj | B12: 볼록성 연간조정 | C12: =Duration!B28 | E12: Duration!B28

Sheet Simulation
A1: [수식 기반 시뮬레이션 (n=100, seed=42)]
A2: Y_inf | B2: =Parameters!C3 | C2: Y_init | D2: =Parameters!C4 | E2: CV_y | F2: =Parameters!C5 | G2: Vol_y | H2: =Parameters!C6
A3: Duration | B3: =Parameters!C7 | C3: 볼록성 | D3: =Parameters!C8 | E3: drift_mean | F3: =Parameters!C9 | G3: drift_med | H3: =Parameters!C10
A5: [4모델 비교]
A6: 모델 | B6: drift | C6: 볼록성 | D6: Year 0 | E6: Year 1 | F6: Year 2 | G6: Year 3 | H6: Year 4 | I6: Year 5 | J6: 1Y 증가율 | K6: 5Y 연환산
A7: A. 보정평균 | B7: =$F$3 | C7: X | D7: =B13 | E7: =C13 | F7: =D13 | G7: =E13 | H7: =F13 | I7: =G13 | J7: =B27 | K7: =B20
A8: B. 보정평균+볼록성 | B8: =$F$3 | C8: O | D8: =B30 | E8: =C30 | F8: =D30 | G8: =E30 | H8: =F30 | I8: =G30 | J8: =B44 | K8: =B37
A9: C. 보정중앙값 | B9: =$H$3 | C9: X | D9: =B47 | E9: =C47 | F9: =D47 | G9: =E47 | H9: =F47 | I9: =G47 | J9: =B61 | K9: =B54
A10: D. 보정중앙값+볼록성 | B10: =$H$3 | C10: O | D10: =B64 | E10: =C64 | F10: =D64 | G10: =E64 | H10: =F64 | I10: =G64 | J10: =B78 | K10: =B71
A12: [모델 A 통계: 보정평균]
A13: Mean | B13: =AVERAGE(B84:B183) | C13: =AVERAGE(C84:C183) | D13: =AVERAGE(D84:D183) | E13: =AVERAGE(E84:E183) | F13: =AVERAGE(F84:F183) | G13: =AVERAGE(G84:G183)
A14: Median | B14: =MEDIAN(B84:B183) | C14: =MEDIAN(C84:C183) | D14: =MEDIAN(D84:D183) | E14: =MEDIAN(E84:E183) | F14: =MEDIAN(F84:F183) | G14: =MEDIAN(G84:G183)
A15: 5th | B15: =PERCENTILE(B84:B183,0.05) | C15: =PERCENTILE(C84:C183,0.05) | D15: =PERCENTILE(D84:D183,0.05) | E15: =PERCENTILE(E84:E183,0.05) | F15: =PERCENTILE(F84:F183,0.05) | G15: =PERCENTILE(G84:G183,0.05)
A16: 25th | B16: =PERCENTILE(B84:B183,0.25) | C16: =PERCENTILE(C84:C183,0.25) | D16: =PERCENTILE(D84:D183,0.25) | E16: =PERCENTILE(E84:E183,0.25) | F16: =PERCENTILE(F84:F183,0.25) | G16: =PERCENTILE(G84:G183,0.25)
A17: 75th | B17: =PERCENTILE(B84:B183,0.75) | C17: =PERCENTILE(C84:C183,0.75) | D17: =PERCENTILE(D84:D183,0.75) | E17: =PERCENTILE(E84:E183,0.75) | F17: =PERCENTILE(F84:F183,0.75) | G17: =PERCENTILE(G84:G183,0.75)
A18: 95th | B18: =PERCENTILE(B84:B183,0.95) | C18: =PERCENTILE(C84:C183,0.95) | D18: =PERCENTILE(D84:D183,0.95) | E18: =PERCENTILE(E84:E183,0.95) | F18: =PERCENTILE(F84:F183,0.95) | G18: =PERCENTILE(G84:G183,0.95)
A20: Mean 연환산 | B20: =(G13/100)^(1/5)-1
A21: Median 연환산 | B21: =(G14/100)^(1/5)-1
A22: 5th 연환산 | B22: =(G15/100)^(1/5)-1
A23: 25th 연환산 | B23: =(G16/100)^(1/5)-1
A24: 75th 연환산 | B24: =(G17/100)^(1/5)-1
A25: 95th 연환산 | B25: =(G18/100)^(1/5)-1
A27: 1Y 증가율(Mean) | B27: =C13-100
A29: [모델 B 통계: 보정평균+볼록성]
A30: Mean | B30: =AVERAGE(B188:B287) | C30: =AVERAGE(C188:C287) | D30: =AVERAGE(D188:D287) | E30: =AVERAGE(E188:E287) | F30: =AVERAGE(F188:F287) | G30: =AVERAGE(G188:G287)
A31: Median | B31: =MEDIAN(B188:B287) | C31: =MEDIAN(C188:C287) | D31: =MEDIAN(D188:D287) | E31: =MEDIAN(E188:E287) | F31: =MEDIAN(F188:F287) | G31: =MEDIAN(G188:G287)
A32: 5th | B32: =PERCENTILE(B188:B287,0.05) | C32: =PERCENTILE(C188:C287,0.05) | D32: =PERCENTILE(D188:D287,0.05) | E32: =PERCENTILE(E188:E287,0.05) | F32: =PERCENTILE(F188:F287,0.05) | G32: =PERCENTILE(G188:G287,0.05)
A33: 25th | B33: =PERCENTILE(B188:B287,0.25) | C33: =PERCENTILE(C188:C287,0.25) | D33: =PERCENTILE(D188:D287,0.25) | E33: =PERCENTILE(E188:E287,0.25) | F33: =PERCENTILE(F188:F287,0.25) | G33: =PERCENTILE(G188:G287,0.25)
A34: 75th | B34: =PERCENTILE(B188:B287,0.75) | C34: =PERCENTILE(C188:C287,0.75) | D34: =PERCENTILE(D188:D287,0.75) | E34: =PERCENTILE(E188:E287,0.75) | F34: =PERCENTILE(F188:F287,0.75) | G34: =PERCENTILE(G188:G287,0.75)
A35: 95th | B35: =PERCENTILE(B188:B287,0.95) | C35: =PERCENTILE(C188:C287,0.95) | D35: =PERCENTILE(D188:D287,0.95) | E35: =PERCENTILE(E188:E287,0.95) | F35: =PERCENTILE(F188:F287,0.95) | G35: =PERCENTILE(G188:G287,0.95)
A37: Mean 연환산 | B37: =(G30/100)^(1/5)-1
A38: Median 연환산 | B38: =(G31/100)^(1/5)-1
A39: 5th 연환산 | B39: =(G32/100)^(1/5)-1
A40: 25th 연환산 | B40: =(G33/100)^(1/5)-1
A41: 75th 연환산 | B41: =(G34/100)^(1/5)-1
A42: 95th 연환산 | B42: =(G35/100)^(1/5)-1
A44: 1Y 증가율(Mean) | B44: =C30-100
A46: [모델 C 통계: 보정중앙값]
A47: Mean | B47: =AVERAGE(B292:B391) | C47: =AVERAGE(C292:C391) | D47: =AVERAGE(D292:D391) | E47: =AVERAGE(E292:E391) | F47: =AVERAGE(F292:F391) | G47: =AVERAGE(G292:G391)
A48: Median | B48: =MEDIAN(B292:B391) | C48: =MEDIAN(C292:C391) | D48: =MEDIAN(D292:D391) | E48: =MEDIAN(E292:E391) | F48: =MEDIAN(F292:F391) | G48: =MEDIAN(G292:G391)
...

Sheet Summary_Python
A1: [Python 시뮬레이션 (n=10K, seed=42) — 검증용]
A2: 파라미터
A3: 파라미터 | B3: 의미 | C3: 산출값 | D3: 산출 방법
A4: Y_inf | B4: 할인율 장기균형 | C4: 0.033893 | D4: 연도별 평균의 평균
A5: Y_init | B5: 할인율 현재값 (2025) | C5: 0.04369 | D5: 2025 연도평균
A6: CV_y | B6: 할인율 회귀속도 | C6: 0.3193 | D6: 패널 MLE
A7: Vol_y | B7: 할인율 변동성 | C7: 0.009724 | D7: 연도별 평균의 std
A8: Duration | B8: 유효듀레이션 (최근5Y) | C8: 6.46 | D8: 민감도 역산, 최근 5년 평균
A9: 볼록성 | B9: 볼록성 (최근3Y) | C9: 85.3 | D9: 민감도 역산, 최근 3년 평균
A10: drift_mean | B10: drift 보정평균 | C10: 0.0668 | D10: (SC-BP+IC)/DBO_{t-1} 평균
A11: drift_median | B11: drift 보정중앙값 | C11: 0.0761 | D11: (SC-BP+IC)/DBO_{t-1} 중앙값
A12: rho | B12: 상관계수 (참고) | C12: 0.6482 | D12: 연도평균 delta 상관
A15: [4모델 비교 (10K, seed=42)]
A16: 모델 | B16: drift | C16: 볼록성 | D16: Year 0 | E16: Year 1 | F16: Year 2 | G16: Year 3 | H16: Year 4 | I16: Year 5 | J16: 1Y 증가율 | K16: 5Y 연환산
A17: A. 보정평균(6.7%) | B17: 6.68 | C17: X | D17: 100 | E17: 108.7 | F17: 117.23 | G17: 126.06 | H17: 135.08 | I17: 144.4 | J17: 8.7 | K17: 7.62
A18: B. 보정평균(6.7%)+볼록성 | B18: 6.68 | C18: O | D18: 100 | E18: 109.16 | F18: 118.21 | G18: 127.68 | H18: 137.41 | I18: 147.53 | J18: 9.16 | K18: 8.09
A19: C. 보정중앙값(7.6%) | B19: 7.61 | C19: X | D19: 100 | E19: 109.63 | F19: 119.26 | G19: 129.36 | H19: 139.82 | I19: 150.77 | J19: 9.63 | K19: 8.56
A20: D. 보정중앙값(7.6%)+볼록성 | B20: 7.61 | C20: O | D20: 100 | E20: 110.09 | F20: 120.25 | G20: 131.01 | H20: 142.21 | I20: 154.01 | J20: 10.09 | K20: 9.02
A23: [모델 A 분위수]
A24: 통계 | B24: Year 0 | C24: Year 1 | D24: Year 2 | E24: Year 3 | F24: Year 4 | G24: Year 5 | H24: 5Y 연환산
A25: Mean | B25: 100 | C25: 108.7 | D25: 117.23 | E25: 126.06 | F25: 135.08 | G25: 144.4 | H25: 7.62
A26: Stdev | B26: 0 | C26: 6.38 | D26: 8.3 | E26: 9.57 | F26: 10.57 | G26: 11.42 | H26: -35.21
A27: 5th | B27: 100 | C27: 98.19 | D27: 103.93 | E27: 111.09 | F27: 118.36 | G27: 126.25 | H27: 4.77
A28: 25th | B28: 100 | C28: 104.4 | D28: 111.57 | E28: 119.29 | F28: 127.8 | G28: 136.45 | H28: 6.41
A29: Median | B29: 100 | C29: 108.62 | D29: 117.07 | E29: 125.8 | F29: 134.8 | G29: 143.94 | H29: 7.56
A30: 75th | B30: 100 | C30: 113.08 | D30: 122.72 | E30: 132.52 | F30: 142.07 | G30: 152.13 | H30: 8.75
A31: 95th | B31: 100 | C31: 119.22 | D31: 131.24 | E31: 142.08 | F31: 152.72 | G31: 163.38 | H31: 10.32
A32: Min | B32: 100 | C32: 84.03 | D32: 83.67 | E32: 91.68 | F32: 99.72 | G32: 108.54 | H32: 1.65
A33: Max | B33: 100 | C33: 135.7 | D33: 151.2 | E33: 165.25 | F33: 174.48 | G33: 194.97 | H33: 14.29
A35: [모델 B 분위수]
A36: 통계 | B36: Year 0 | C36: Year 1 | D36: Year 2 | E36: Year 3 | F36: Year 4 | G36: Year 5 | H36: 5Y 연환산
A37: Mean | B37: 100 | C37: 109.16 | D37: 118.21 | E37: 127.68 | F37: 137.41 | G37: 147.53 | H37: 8.09
A38: Stdev | B38: 0 | C38: 6.68 | D38: 8.63 | E38: 9.92 | F38: 10.93 | G38: 11.81 | H38: -34.77
A39: 5th | B39: 100 | C39: 98.93 | D39: 104.87 | E39: 112.57 | F39: 120.55 | G39: 129.29 | H39: 5.27
A40: 25th | B40: 100 | C40: 104.46 | D40: 112.14 | E40: 120.61 | F40: 129.81 | G40: 139.18 | H40: 6.84
A41: Median | B41: 100 | C41: 108.66 | D41: 117.74 | E41: 127.17 | F41: 136.9 | G41: 146.93 | H41: 8
A42: 75th | B42: 100 | C42: 113.5 | D42: 123.67 | E42: 134.12 | F42: 144.45 | G42: 155.09 | H42: 9.17
A43: 95th | B43: 100 | C43: 120.83 | D43: 133.2 | E43: 144.75 | F43: 156.09 | G43: 167.4 | H43: 10.85
A44: Min | B44: 100 | C44: 89.26 | D44: 88.61 | E44: 96.23 | F44: 102.22 | G44: 114.61 | H44: 2.76
A45: Max | B45: 100 | C45: 144.29 | D45: 161.11 | E45: 172.42 | F45: 182.17 | G45: 205.56 | H45: 15.5
...

Sheet Comparison
A1: [Python(n=10K) vs Excel(n=100) 비교]
A2: 항목 | B2: Python(n=10K) | C2: Excel(n=100) | D2: 차이
A3: [모델별 성과]
A4: 모델 A 1Y증가율 | B4: =Summary_Python!J17 | C4: =Simulation!B27 | D4: =C4-B4
A5: 모델 A 5Y연환산 | B5: =Summary_Python!K17 | C5: =Simulation!B20*100 | D5: =C5-B5
A6: 모델 B 1Y증가율 | B6: =Summary_Python!J18 | C6: =Simulation!B44 | D6: =C6-B6
A7: 모델 B 5Y연환산 | B7: =Summary_Python!K18 | C7: =Simulation!B37*100 | D7: =C7-B7
A8: 모델 C 1Y증가율 | B8: =Summary_Python!J19 | C8: =Simulation!B61 | D8: =C8-B8
A9: 모델 C 5Y연환산 | B9: =Summary_Python!K19 | C9: =Simulation!B54*100 | D9: =C9-B9
A10: 모델 D 1Y증가율 | B10: =Summary_Python!J20 | C10: =Simulation!B78 | D10: =C10-B10
A11: 모델 D 5Y연환산 | B11: =Summary_Python!K20 | C11: =Simulation!B71*100 | D11: =C11-B11
A13: [파라미터]
A14: Y_inf | B14: =Summary_Python!C4 | C14: =Parameters!C3 | D14: =C14-B14
A15: Y_init | B15: =Summary_Python!C5 | C15: =Parameters!C4 | D15: =C15-B15
A16: CV_y | B16: =Summary_Python!C6 | C16: =Parameters!C5 | D16: =C16-B16
A17: Vol_y | B17: =Summary_Python!C7 | C17: =Parameters!C6 | D17: =C17-B17
A18: Duration | B18: =Summary_Python!C8 | C18: =Parameters!C7 | D18: =C18-B18
A19: 볼록성 | B19: =Summary_Python!C9 | C19: =Parameters!C8 | D19: =C19-B19
A20: drift_mean | B20: =Summary_Python!C10 | C20: =Parameters!C9 | D20: =C20-B20
A21: drift_median | B21: =Summary_Python!C11 | C21: =Parameters!C10 | D21: =C21-B21
A22: rho | B22: =Summary_Python!C12 | C22: =Parameters!C11 | D22: =C22-B22
